Workbook

Sheet PAR-011
B1: LỊCH GIAO HÀNG DO SUNG DO SUNG会社の納品スケジュール
B5: 2026 | D5: 年 | E5: 1 | F5: 月
A6: JOINTER PAR-011 | B6: 輸送 | D6: 日 | G6: =DATE(B5,E5,1) | H6: =IF(G6="","",IF(DAY(G6+1)=1,"",G6+1)) | I6: =IF(H6="","",IF(DAY(H6+1)=1,"",H6+1)) | J6: =IF(I6="","",IF(DAY(I6+1)=1,"",I6+1)) | K6: =IF(J6="","",IF(DAY(J6+1)=1,"",J6+1)) | L6: =IF(K6="","",IF(DAY(K6+1)=1,"",K6+1)) | M6: =IF(L6="","",IF(DAY(L6+1)=1,"",L6+1)) | N6: =IF(M6="","",IF(DAY(M6+1)=1,"",M6+1)) | O6: =IF(N6="","",IF(DAY(N6+1)=1,"",N6+1)) | ... AK6: =IF(AJ6="","",IF(DAY(AJ6+1)=1,"",AJ6+1)) | AL6: Total
D7: 時間 | G7: =+G6 | H7: =+H6 | I7: =+I6 | J7: =+J6 | K7: =+K6 | L7: =+L6 | M7: =+M6 | N7: =+N6 | ... AK7: =+AK6
B8: PO 注文書 | L8: 5000 | R8: 5000 | Y8: 5000 | AF8: 5000 | AL8: =SUM(G8:AK8) | AN8: Tồn PO 注文の 残量 | AO8: =14613+AL8-AO9
B9: 計画数量 kế hoạch | H9: 480 | K9: 1200 | L9: 1200 | M9: 1000 | N9: 600 | O9: 870 | R9: 1350 | S9: 420 | T9: 1000 | U9: 1000 | V9: 1000 | W9: 1000 | Y9: 1000 | Z9: 1000 | AA9: 1000 | AB9: 1000 | AC9: 1000 | AD9: 1000 | AF9: 1000 | AG9: 1000 | AH9: 1000 | AI9: 1000 | AJ9: 1000 | AK9: 1000 | AL9: =SUM(G9:AK9) | AN9: Tổng nhập 総入荷数量 （A)-(B)+(C) | AO9: =AL10-AL11+AL12
B10: 実際の納品数量 số lượng thực nhập | H10: 480 | K10: 1200 | L10: 1200 | N10: 600 | O10: 870 | R10: 1350 | S10: 420 | U10: 1050 | V10: 1500 | W10: 1110 | Y10: 1050 | Z10: 750 | AA10: 1020 | AB10: 750 | AC10: 1140 | AD10: 600 | AF10: 1110 | AG10: 510 | AH10: 750 | AI10: 900 | AJ10: 1200 | AK10: 1200 | AL10: =SUM(G10:AK10) | AM10: (A) | AN10: Số lượng chưa khai tháng trước 先月まだ税関に申告されていない数量 | AO10: 3417
B11: NG数量（DO SUNG 社変更済） số lượng NG (Trả hàng DO SUNG) | AI11: 275 | AL11: =SUM(G11:AK11) | AM11: (B) | AN11: Số lượng đã khai tháng này 今月税関に申告された数量 | AO11: =20000+2702
B12: NG数量（DO SUNG 社しゅり済） số lượng NG (DO SUNG đã sửa ) | AL12: =SUM(G12:AK12) | AM12: (C) | AN12: Số lượng còn lại chưa khai 残りの数量はまだ税関に申告されていません | AO12: =AO10+AO9-AO11
B14: 2026 | D14: 年 | E14: 2 | F14: 月
A15: JOINTER PAR-011 | B15: 輸送 | D15: 日 | G15: =DATE(B14,E14,1) | H15: =IF(G15="","",IF(DAY(G15+1)=1,"",G15+1)) | I15: =IF(H15="","",IF(DAY(H15+1)=1,"",H15+1)) | J15: =IF(I15="","",IF(DAY(I15+1)=1,"",I15+1)) | K15: =IF(J15="","",IF(DAY(J15+1)=1,"",J15+1)) | L15: =IF(K15="","",IF(DAY(K15+1)=1,"",K15+1)) | M15: =IF(L15="","",IF(DAY(L15+1)=1,"",L15+1)) | N15: =IF(M15="","",IF(DAY(M15+1)=1,"",M15+1)) | O15: =IF(N15="","",IF(DAY(N15+1)=1,"",N15+1)) | ... AK15: =IF(AJ15="","",IF(DAY(AJ15+1)=1,"",AJ15+1)) | AL15: Total
D16: 時間 | G16: =+G15 | H16: =+H15 | I16: =+I15 | J16: =+J15 | K16: =+K15 | L16: =+L15 | M16: =+M15 | N16: =+N15 | ... AK16: =+AK15
B17: PO 注文書 | H17: 5000 | O17: 5000 | AL17: =SUM(G17:AK17) | AN17: Tồn PO 注文の 残量 | AO17: =AO8+AL17-AO18
B18: 計画数量 kế hoạch | H18: 1000 | I18: 1000 | J18: 1000 | K18: 1000 | L18: 1000 | M18: 1000 | O18: 1000 | P18: 1000 | Q18: 1000 | R18: 1000 | S18: 1000 | T18: 705 | AG18: 1000 | AH18: 1000 | AL18: =SUM(G18:AK18) | AN18: Tổng nhập 総入荷数量 （A)-(B)+(C) | AO18: =AL19-AL20+AL21
B19: 実際の納品数量 số lượng thực nhập | H19: 1200 | I19: 1350 | J19: 1800 | K19: 1200 | L19: 1320 | M19: 1200 | O19: 1200 | P19: 1200 | Q19: 1200 | AG19: 1200 | AH19: 1200 | AL19: =SUM(G19:AK19) | AM19: (A) | AN19: Số lượng chưa khai tháng trước 先月まだ税関に申告されていない数量 | AO19: =AO12
B20: NG数量（DO SUNG 社変更済） số lượng NG (Trả hàng DO SUNG) | I20: =14+101 | AL20: =SUM(G20:AK20) | AM20: (B) | AN20: Số lượng đã khai tháng này 今月税関に申告された数量 | AO20: 12955
B21: NG数量（DO SUNG 社しゅり済） số lượng NG (DO SUNG đã sửa ) | AL21: =SUM(G21:AK21) | AM21: (C) | AN21: Số lượng còn lại chưa khai 残りの数量はまだ税関に申告されていません | AO21: =AO19+AO18-AO20
B23: 2026 | D23: 年 | E23: 3 | F23: 月
A24: JOINTER PAR-011 | B24: 輸送 | D24: 日 | G24: =DATE(B23,E23,1) | H24: =IF(G24="","",IF(DAY(G24+1)=1,"",G24+1)) | I24: =IF(H24="","",IF(DAY(H24+1)=1,"",H24+1)) | J24: =IF(I24="","",IF(DAY(I24+1)=1,"",I24+1)) | K24: =IF(J24="","",IF(DAY(J24+1)=1,"",J24+1)) | L24: =IF(K24="","",IF(DAY(K24+1)=1,"",K24+1)) | M24: =IF(L24="","",IF(DAY(L24+1)=1,"",L24+1)) | N24: =IF(M24="","",IF(DAY(M24+1)=1,"",M24+1)) | O24: =IF(N24="","",IF(DAY(N24+1)=1,"",N24+1)) | ... AK24: =IF(AJ24="","",IF(DAY(AJ24+1)=1,"",AJ24+1)) | AL24: Total
D25: 時間 | G25: =+G24 | H25: =+H24 | I25: =+I24 | J25: =+J24 | K25: =+K24 | L25: =+L24 | M25: =+M24 | N25: =+N24 | ... AK25: =+AK24
B26: PO 注文書 | H26: 5000 | O26: 5000 | V26: 5000 | AC26: 6000 | AJ26: 6000 | AL26: =SUM(G26:AK26) | AN26: Tồn PO 注文の 残量 | AO26: =AO17+AL26-AO27
B27: 計画数量 kế hoạch | H27: 1500 | I27: 1000 | J27: 1000 | K27: 1000 | L27: 1000 | O27: 1200 | P27: 1200 | Q27: 1200 | R27: 1200 | S27: 1200 | T27: 1200 | V27: 1200 | W27: 1200 | X27: 1200 | Y27: 1200 | Z27: 1200 | AC27: 1200 | AD27: 1200 | AE27: 1200 | AF27: 1200 | AL27: =SUM(G27:AK27) | AN27: Tổng nhập 総入荷数量 （A)-(B)+(C) | AO27: =AL28-AL29+AL30
B28: 実際の納品数量 số lượng thực nhập | H28: 1080 | I28: 1200 | J28: 1200 | K28: 1200 | L28: 1200 | O28: 1950 | P28: 1200 | Q28: 1200 | R28: 1200 | S28: 1200 | T28: 1200 | W28: 960 | X28: 1200 | Z28: 1200 | AA28: 1200 | AC28: 2400 | AD28: 1200 | AE28: 1200 | AF28: 1200 | AG28: 1200 | AH28: 1200 | AL28: =SUM(G28:AK28) | AM28: (A) | AN28: Số lượng chưa khai tháng trước 先月まだ税関に申告されていない数量 | AO28: =AO21
B29: NG数量（DO SUNG 社変更済） số lượng NG (Trả hàng DO SUNG) | AL29: =SUM(G29:AK29) | AM29: (B) | AN29: Số lượng đã khai tháng này 今月税関に申告された数量 | AO29: =7700+14330+6960
B30: NG数量（DO SUNG 社しゅり済） số lượng NG (DO SUNG đã sửa ) | AL30: =SUM(G30:AK30) | AM30: (C) | AN30: Số lượng còn lại chưa khai 残りの数量はまだ税関に申告されていません | AO30: =AO28+AO27-AO29
B32: 2026 | D32: 年 | E32: 4 | F32: 月
A33: JOINTER PAR-011 | B33: 輸送 | D33: 日 | G33: =DATE(B32,E32,1) | H33: =IF(G33="","",IF(DAY(G33+1)=1,"",G33+1)) | I33: =IF(H33="","",IF(DAY(H33+1)=1,"",H33+1)) | J33: =IF(I33="","",IF(DAY(I33+1)=1,"",I33+1)) | K33: =IF(J33="","",IF(DAY(J33+1)=1,"",J33+1)) | L33: =IF(K33="","",IF(DAY(K33+1)=1,"",K33+1)) | M33: =IF(L33="","",IF(DAY(L33+1)=1,"",L33+1)) | N33: =IF(M33="","",IF(DAY(M33+1)=1,"",M33+1)) | O33: =IF(N33="","",IF(DAY(N33+1)=1,"",N33+1)) | ... AK33: =IF(AJ33="","",IF(DAY(AJ33+1)=1,"",AJ33+1)) | AL33: Total
D34: 時間 | G34: =+G33 | H34: =+H33 | I34: =+I33 | J34: =+J33 | K34: =+K33 | L34: =+L33 | M34: =+M33 | N34: =+N33 | ... AK34: =+AK33
B35: PO 注文書 | L35: 6000 | S35: 6000 | Z35: 6000 | AL35: =SUM(G35:AK35) | AN35: Tồn PO 注文の 残量 | AO35: =AO26+AL35-AO36
B36: 計画数量 kế hoạch | G36: 1200 | H36: 1200 | I36: 1200 | J36: 1200 | L36: 1200 | M36: 1200 | N36: 1200 | O36: 1200 | P36: 1200 | Q36: 1200 | S36: 1200 | T36: 1200 | U36: 1200 | V36: 1200 | W36: 1200 | X36: 1200 | Z36: 1200 | AA36: 1200 | AB36: 1200 | AC36: 1200 | AD36: 1200 | AE36: 1200 | AG36: 1200 | AH36: 1200 | AI36: 1200 | AL36: =SUM(G36:AK36) | AN36: Tổng nhập 総入荷数量 （A)-(B)+(C) | AO36: =AL37-AL38+AL39
B37: 実際の納品数量 số lượng thực nhập | G37: 2400 | H37: 1200 | I37: 1200 | J37: 1200 | L37: 1200 | M37: 1200 | N37: 1200 | O37: 1200 | P37: 1200 | S37: 2400 | T37: 1200 | U37: 1200 | V37: 1200 | W37: 1200 | X37: 1200 | AA37: 1200 | AC37: 2400 | AD37: 3600 | AH37: 3568 | AL37: =SUM(G37:AK37) | AM37: (A) | AN37: Số lượng chưa khai tháng trước 先月まだ税関に申告されていない数量 | AO37: =AO30
B38: NG数量（DO SUNG 社変更済） số lượng NG (Trả hàng DO SUNG) | AL38: =SUM(G38:AK38) | AM38: (B) | AN38: Số lượng đã khai tháng này 今月税関に申告された数量 | AO38: =12000+8000+7400
B39: NG数量（DO SUNG 社しゅり済） số lượng NG (DO SUNG đã sửa ) | AL39: =SUM(G39:AK39) | AM39: (C) | AN39: Số lượng còn lại chưa khai 残りの数量はまだ税関に申告されていません | AO39: =AO37+AO36-AO38
B41: 2026 | D41: 年 | E41: 5 | F41: 月
A42: JOINTER PAR-011 | B42: 輸送 | D42: 日 | G42: =DATE(B41,E41,1) | H42: =IF(G42="","",IF(DAY(G42+1)=1,"",G42+1)) | I42: =IF(H42="","",IF(DAY(H42+1)=1,"",H42+1)) | J42: =IF(I42="","",IF(DAY(I42+1)=1,"",I42+1)) | K42: =IF(J42="","",IF(DAY(J42+1)=1,"",J42+1)) | L42: =IF(K42="","",IF(DAY(K42+1)=1,"",K42+1)) | M42: =IF(L42="","",IF(DAY(L42+1)=1,"",L42+1)) | N42: =IF(M42="","",IF(DAY(M42+1)=1,"",M42+1)) | O42: =IF(N42="","",IF(DAY(N42+1)=1,"",N42+1)) | ... AK42: =IF(AJ42="","",IF(DAY(AJ42+1)=1,"",AJ42+1)) | AL42: Total
D43: 時間 | G43: =+G42 | H43: =+H42 | I43: =+I42 | J43: =+J42 | K43: =+K42 | L43: =+L42 | M43: =+M42 | N43: =+N42 | ... AK43: =+AK42
B44: PO 注文書 | J44: 7500 | Q44: 7500 | X44: 7500 | AE44: 7500 | AL44: =SUM(G44:AK44) | AN44: Tồn PO 注文の 残量 | AO44: =AO35+AL44-AO45
B45: 計画数量 kế hoạch | J45: 3600 | M45: 3600 | Q45: 3600 | T45: 3600 | X45: 3600 | AA45: 3600 | AE45: 3600 | AH45: 3600 | AL45: =SUM(G45:AK45) | AN45: Tổng nhập 総入荷数量 （A)-(B)+(C) | AO45: =AL46-AL47+AL48
B46: 実際の納品数量 số lượng thực nhập | L46: 2400 | M46: 2400 | Q46: 3600 | T46: 3600 | X46: 2400 | AA46: 2400 | AE46: 3600 | AH46: 3600 | AL46: =SUM(G46:AK46) | AM46: (A) | AN46: Số lượng chưa khai tháng trước 先月まだ税関に申告されていない数量 | AO46: =AO39
B47: NG数量（DO SUNG 社変更済） số lượng NG (Trả hàng DO SUNG) | L47: 306 | AL47: =SUM(G47:AK47) | AM47: (B) | AN47: Số lượng đã khai tháng này 今月税関に申告された数量 | AO47: =6968+15200+5294
...

Sheet PJ420
B1: LỊCH GIAO HÀNG DO SUNG DO SUNG会社の納品スケジュール
B5: 2026 | D5: 年 | E5: 1 | F5: 月
A6: mda0017 DLW231002-001 | B6: 輸送 | D6: 日 | G6: =DATE(B5,E5,1) | H6: =IF(G6="","",IF(DAY(G6+1)=1,"",G6+1)) | I6: =IF(H6="","",IF(DAY(H6+1)=1,"",H6+1)) | J6: =IF(I6="","",IF(DAY(I6+1)=1,"",I6+1)) | K6: =IF(J6="","",IF(DAY(J6+1)=1,"",J6+1)) | L6: =IF(K6="","",IF(DAY(K6+1)=1,"",K6+1)) | M6: =IF(L6="","",IF(DAY(L6+1)=1,"",L6+1)) | N6: =IF(M6="","",IF(DAY(M6+1)=1,"",M6+1)) | O6: =IF(N6="","",IF(DAY(N6+1)=1,"",N6+1)) | ... AK6: =IF(AJ6="","",IF(DAY(AJ6+1)=1,"",AJ6+1)) | AL6: Total
D7: 時間 | G7: =+G6 | H7: =+H6 | I7: =+I6 | J7: =+J6 | K7: =+K6 | L7: =+L6 | M7: =+M6 | N7: =+N6 | ... AK7: =+AK6
B8: PO 注文書 | AJ8: 100 | AL8: =SUM(G8:AK8) | AN8: Tồn PO 注文の 残量 | AO8: =AL8-AO9
B9: 計画数量 kế hoạch | AL9: =SUM(G9:AK9) | AN9: Tổng nhập 総入荷数量 （A)-(B)+(C) | AO9: =AL10-AL11+AL12
B10: 実際の納品数量 số lượng thực nhập | N10: 100 | AL10: =SUM(G10:AK10) | AM10: (A) | AN10: Số lượng chưa khai tháng trước 先月まだ税関に申告されていない数量
B11: NG数量（DO SUNG 社変更済） số lượng NG (Trả hàng DO SUNG) | AL11: =SUM(G11:AK11) | AM11: (B) | AN11: Số lượng đã khai tháng này 今月税関に申告された数量 | AO11: 100
B12: NG数量（ドンスン 社しゅり済） số lượng NG (DO SUNG đã sửa ) | AL12: =SUM(G12:AK12) | AM12: (C) | AN12: Số lượng còn lại chưa khai 残りの数量はまだ税関に申告されていません | AO12: =AO10+AO9-AO11
B14: 2026 | D14: 年 | E14: 2 | F14: 月
A15: mda0017 DLW231002-001 | B15: 輸送 | D15: 日 | G15: =DATE(B14,E14,1) | H15: =IF(G15="","",IF(DAY(G15+1)=1,"",G15+1)) | I15: =IF(H15="","",IF(DAY(H15+1)=1,"",H15+1)) | J15: =IF(I15="","",IF(DAY(I15+1)=1,"",I15+1)) | K15: =IF(J15="","",IF(DAY(J15+1)=1,"",J15+1)) | L15: =IF(K15="","",IF(DAY(K15+1)=1,"",K15+1)) | M15: =IF(L15="","",IF(DAY(L15+1)=1,"",L15+1)) | N15: =IF(M15="","",IF(DAY(M15+1)=1,"",M15+1)) | O15: =IF(N15="","",IF(DAY(N15+1)=1,"",N15+1)) | ... AK15: =IF(AJ15="","",IF(DAY(AJ15+1)=1,"",AJ15+1)) | AL15: Total
D16: 時間 | G16: =+G15 | H16: =+H15 | I16: =+I15 | J16: =+J15 | K16: =+K15 | L16: =+L15 | M16: =+M15 | N16: =+N15 | ... AK16: =+AK15
B17: PO 注文書 | AL17: =SUM(G17:AK17) | AN17: Tồn PO 注文の 残量 | AO17: =AO12+AL17-AO18
B18: 計画数量 kế hoạch | AL18: =SUM(G18:AK18) | AN18: Tổng nhập 総入荷数量 （A)-(B)+(C) | AO18: =AL19-AL20+AL21
B19: 実際の納品数量 số lượng thực nhập | M19: 112 | AL19: =SUM(G19:AK19) | AM19: (A) | AN19: Số lượng chưa khai tháng trước 先月まだ税関に申告されていない数量 | AO19: =AO12
B20: NG数量（DO SUNG 社変更済） số lượng NG (Trả hàng DO SUNG) | AL20: =SUM(G20:AK20) | AM20: (B) | AN20: Số lượng đã khai tháng này 今月税関に申告された数量
B21: NG数量（ドンスン 社しゅり済） số lượng NG (DO SUNG đã sửa ) | AL21: =SUM(G21:AK21) | AM21: (C) | AN21: Số lượng còn lại chưa khai 残りの数量はまだ税関に申告されていません | AO21: =AO19+AO18-AO20
B23: 2026 | D23: 年 | E23: 3 | F23: 月
A24: mda0017 DLW231002-001 | B24: 輸送 | D24: 日 | G24: =DATE(B23,E23,1) | H24: =IF(G24="","",IF(DAY(G24+1)=1,"",G24+1)) | I24: =IF(H24="","",IF(DAY(H24+1)=1,"",H24+1)) | J24: =IF(I24="","",IF(DAY(I24+1)=1,"",I24+1)) | K24: =IF(J24="","",IF(DAY(J24+1)=1,"",J24+1)) | L24: =IF(K24="","",IF(DAY(K24+1)=1,"",K24+1)) | M24: =IF(L24="","",IF(DAY(L24+1)=1,"",L24+1)) | N24: =IF(M24="","",IF(DAY(M24+1)=1,"",M24+1)) | O24: =IF(N24="","",IF(DAY(N24+1)=1,"",N24+1)) | ... AK24: =IF(AJ24="","",IF(DAY(AJ24+1)=1,"",AJ24+1)) | AL24: Total
D25: 時間 | G25: =+G24 | H25: =+H24 | I25: =+I24 | J25: =+J24 | K25: =+K24 | L25: =+L24 | M25: =+M24 | N25: =+N24 | ... AK25: =+AK24
B26: PO 注文書 | AL26: =SUM(G26:AK26) | AN26: Tồn PO 注文の 残量 | AO26: =AO21+AL26-AO27
B27: 計画数量 kế hoạch | AL27: =SUM(G27:AK27) | AN27: Tổng nhập 総入荷数量 （A)-(B)+(C) | AO27: =AL28-AL29+AL30
B28: 実際の納品数量 số lượng thực nhập | AL28: =SUM(G28:AK28) | AM28: (A) | AN28: Số lượng chưa khai tháng trước 先月まだ税関に申告されていない数量 | AO28: =AO21
B29: NG数量（DO SUNG 社変更済） số lượng NG (Trả hàng DO SUNG) | I29: 94 | AL29: =SUM(G29:AK29) | AM29: (B) | AN29: Số lượng đã khai tháng này 今月税関に申告された数量 | AO29: 12
B30: NG数量（ドンスン 社しゅり済） số lượng NG (DO SUNG đã sửa ) | AL30: =SUM(G30:AK30) | AM30: (C) | AN30: Số lượng còn lại chưa khai 残りの数量はまだ税関に申告されていません | AO30: =AO28+AO27-AO29
B32: 2026 | D32: 年 | E32: 4 | F32: 月
A33: mda0017 DLW231002-001 | B33: 輸送 | D33: 日 | G33: =DATE(B32,E32,1) | H33: =IF(G33="","",IF(DAY(G33+1)=1,"",G33+1)) | I33: =IF(H33="","",IF(DAY(H33+1)=1,"",H33+1)) | J33: =IF(I33="","",IF(DAY(I33+1)=1,"",I33+1)) | K33: =IF(J33="","",IF(DAY(J33+1)=1,"",J33+1)) | L33: =IF(K33="","",IF(DAY(K33+1)=1,"",K33+1)) | M33: =IF(L33="","",IF(DAY(L33+1)=1,"",L33+1)) | N33: =IF(M33="","",IF(DAY(M33+1)=1,"",M33+1)) | O33: =IF(N33="","",IF(DAY(N33+1)=1,"",N33+1)) | ... AK33: =IF(AJ33="","",IF(DAY(AJ33+1)=1,"",AJ33+1)) | AL33: Total
D34: 時間 | G34: =+G33 | H34: =+H33 | I34: =+I33 | J34: =+J33 | K34: =+K33 | L34: =+L33 | M34: =+M33 | N34: =+N33 | ... AK34: =+AK33
B35: PO 注文書 | AL35: =SUM(G35:AK35) | AN35: Tồn PO 注文の 残量 | AO35: =AO30+AL35-AO36
B36: 計画数量 kế hoạch | AL36: =SUM(G36:AK36) | AN36: Tổng nhập 総入荷数量 （A)-(B)+(C) | AO36: =AL37-AL38+AL39
B37: 実際の納品数量 số lượng thực nhập | AL37: =SUM(G37:AK37) | AM37: (A) | AN37: Số lượng chưa khai tháng trước 先月まだ税関に申告されていない数量 | AO37: =AO30
B38: NG数量（DO SUNG 社変更済） số lượng NG (Trả hàng DO SUNG) | AL38: =SUM(G38:AK38) | AM38: (B) | AN38: Số lượng đã khai tháng này 今月税関に申告された数量
B39: NG数量（ドンスン 社しゅり済） số lượng NG (DO SUNG đã sửa ) | AL39: =SUM(G39:AK39) | AM39: (C) | AN39: Số lượng còn lại chưa khai 残りの数量はまだ税関に申告されていません | AO39: =AO37+AO36-AO38

Sheet mda0018
B1: LỊCH GIAO HÀNG DO SUNG DO SUNG会社の納品スケジュール
B5: 2026 | D5: 年 | E5: 2 | F5: 月
A6: mda0018 Thân khóa tay cầm (có khóa) ンドルロック本体 (キー付き) | B6: 輸送 | D6: 日 | G6: =DATE(B5,E5,1) | H6: =IF(G6="","",IF(DAY(G6+1)=1,"",G6+1)) | I6: =IF(H6="","",IF(DAY(H6+1)=1,"",H6+1)) | J6: =IF(I6="","",IF(DAY(I6+1)=1,"",I6+1)) | K6: =IF(J6="","",IF(DAY(J6+1)=1,"",J6+1)) | L6: =IF(K6="","",IF(DAY(K6+1)=1,"",K6+1)) | M6: =IF(L6="","",IF(DAY(L6+1)=1,"",L6+1)) | N6: =IF(M6="","",IF(DAY(M6+1)=1,"",M6+1)) | O6: =IF(N6="","",IF(DAY(N6+1)=1,"",N6+1)) | ... AK6: =IF(AJ6="","",IF(DAY(AJ6+1)=1,"",AJ6+1)) | AL6: Total
D7: 時間 | G7: =+G6 | H7: =+H6 | I7: =+I6 | J7: =+J6 | K7: =+K6 | L7: =+L6 | M7: =+M6 | N7: =+N6 | ... AK7: =+AK6
B8: PO 注文書 | AL8: =SUM(G8:AK8) | AN8: Tồn PO 注文の 残量
B9: 計画数量 kế hoạch | AL9: =SUM(G9:AK9) | AN9: Tổng nhập 総入荷数量 （A)-(B)+(C) | AO9: =AL10-AL11+AL12
B10: 実際の納品数量 số lượng thực nhập | AG10: 50 | AL10: =SUM(G10:AK10) | AM10: (A) | AN10: Số lượng chưa khai tháng trước 先月まだ税関に申告されていない数量
B11: NG数量（DO SUNG 社変更済） số lượng NG (Trả hàng DO SUNG) | AL11: =SUM(G11:AK11) | AM11: (B) | AN11: Số lượng đã khai tháng này 今月税関に申告された数量
B12: NG数量（ドンスン 社しゅり済） số lượng NG (DO SUNG đã sửa ) | AL12: =SUM(G12:AK12) | AM12: (C) | AN12: Số lượng còn lại chưa khai 残りの数量はまだ税関に申告されていません | AO12: =AO10+AO9-AO11
B14: 2026 | D14: 年 | E14: 3 | F14: 月
A15: mda0018 Thân khóa tay cầm (có khóa) ンドルロック本体 (キー付き) | B15: 輸送 | D15: 日 | G15: =DATE(B14,E14,1) | H15: =IF(G15="","",IF(DAY(G15+1)=1,"",G15+1)) | I15: =IF(H15="","",IF(DAY(H15+1)=1,"",H15+1)) | J15: =IF(I15="","",IF(DAY(I15+1)=1,"",I15+1)) | K15: =IF(J15="","",IF(DAY(J15+1)=1,"",J15+1)) | L15: =IF(K15="","",IF(DAY(K15+1)=1,"",K15+1)) | M15: =IF(L15="","",IF(DAY(L15+1)=1,"",L15+1)) | N15: =IF(M15="","",IF(DAY(M15+1)=1,"",M15+1)) | O15: =IF(N15="","",IF(DAY(N15+1)=1,"",N15+1)) | ... AK15: =IF(AJ15="","",IF(DAY(AJ15+1)=1,"",AJ15+1)) | AL15: Total
D16: 時間 | G16: =+G15 | H16: =+H15 | I16: =+I15 | J16: =+J15 | K16: =+K15 | L16: =+L15 | M16: =+M15 | N16: =+N15 | ... AK16: =+AK15
B17: PO 注文書 | K17: 2200 | AL17: =SUM(G17:AK17) | AN17: Tồn PO 注文の 残量 | AO17: =AO8+AL17-AO18
B18: 計画数量 kế hoạch | AL18: =SUM(G18:AK18) | AN18: Tổng nhập 総入荷数量 （A)-(B)+(C) | AO18: =AL19-AL20+AL21
B19: 実際の納品数量 số lượng thực nhập | J19: 3 | O19: 2150 | AL19: =SUM(G19:AK19) | AM19: (A) | AN19: Số lượng chưa khai tháng trước 先月まだ税関に申告されていない数量 | AO19: =AO12
B20: NG数量（DO SUNG 社変更済） số lượng NG (Trả hàng DO SUNG) | AL20: =SUM(G20:AK20) | AM20: (B) | AN20: Số lượng đã khai tháng này 今月税関に申告された数量 | AO20: 2200
B21: NG数量（ドンスン 社しゅり済） số lượng NG (DO SUNG đã sửa ) | AL21: =SUM(G21:AK21) | AM21: (C) | AN21: Số lượng còn lại chưa khai 残りの数量はまだ税関に申告されていません | AO21: =AO19+AO18-AO20
B23: 2026 | D23: 年 | E23: 5 | F23: 月
A24: mda0018 Thân khóa tay cầm (có khóa) ンドルロック本体 (キー付き) | B24: 輸送 | D24: 日 | G24: =DATE(B23,E23,1) | H24: =IF(G24="","",IF(DAY(G24+1)=1,"",G24+1)) | I24: =IF(H24="","",IF(DAY(H24+1)=1,"",H24+1)) | J24: =IF(I24="","",IF(DAY(I24+1)=1,"",I24+1)) | K24: =IF(J24="","",IF(DAY(J24+1)=1,"",J24+1)) | L24: =IF(K24="","",IF(DAY(K24+1)=1,"",K24+1)) | M24: =IF(L24="","",IF(DAY(L24+1)=1,"",L24+1)) | N24: =IF(M24="","",IF(DAY(M24+1)=1,"",M24+1)) | O24: =IF(N24="","",IF(DAY(N24+1)=1,"",N24+1)) | ... AK24: =IF(AJ24="","",IF(DAY(AJ24+1)=1,"",AJ24+1)) | AL24: Total
D25: 時間 | G25: =+G24 | H25: =+H24 | I25: =+I24 | J25: =+J24 | K25: =+K24 | L25: =+L24 | M25: =+M24 | N25: =+N24 | ... AK25: =+AK24
B26: PO 注文書 | L26: 1200 | AL26: =SUM(G26:AK26) | AN26: Tồn PO 注文の 残量 | AO26: =AO17+AL26-AO27
B27: 計画数量 kế hoạch | AL27: =SUM(G27:AK27) | AN27: Tổng nhập 総入荷数量 （A)-(B)+(C) | AO27: =AL28-AL29+AL30
B28: 実際の納品数量 số lượng thực nhập | Q28: 1200 | AL28: =SUM(G28:AK28) | AM28: (A) | AN28: Số lượng chưa khai tháng trước 先月まだ税関に申告されていない数量 | AO28: =AO21
B29: NG数量（DO SUNG 社変更済） số lượng NG (Trả hàng DO SUNG) | T29: 489 | AL29: =SUM(G29:AK29) | AM29: (B) | AN29: Số lượng đã khai tháng này 今月税関に申告された数量 | AO29: 1200
B30: NG数量（ドンスン 社しゅり済） số lượng NG (DO SUNG đã sửa ) | Q30: 33 | T30: 435 | AL30: =SUM(G30:AK30) | AM30: (C) | AN30: Số lượng còn lại chưa khai 残りの数量はまだ税関に申告されていません | AO30: =AO28+AO27-AO29
B33: 2026 | D33: 年 | E33: 10 | F33: 月 | Q33: 11/07/2026 đặt PO
A34: mda0018 Thân khóa tay cầm (có khóa) ンドルロック本体 (キー付き) | B34: 輸送 | D34: 日 | G34: =DATE(B33,E33,1) | H34: =IF(G34="","",IF(DAY(G34+1)=1,"",G34+1)) | I34: =IF(H34="","",IF(DAY(H34+1)=1,"",H34+1)) | J34: =IF(I34="","",IF(DAY(I34+1)=1,"",I34+1)) | K34: =IF(J34="","",IF(DAY(J34+1)=1,"",J34+1)) | L34: =IF(K34="","",IF(DAY(K34+1)=1,"",K34+1)) | M34: =IF(L34="","",IF(DAY(L34+1)=1,"",L34+1)) | N34: =IF(M34="","",IF(DAY(M34+1)=1,"",M34+1)) | O34: =IF(N34="","",IF(DAY(N34+1)=1,"",N34+1)) | ... AK34: =IF(AJ34="","",IF(DAY(AJ34+1)=1,"",AJ34+1)) | AL34: Total
D35: 時間 | G35: =+G34 | H35: =+H34 | I35: =+I34 | J35: =+J34 | K35: =+K34 | L35: =+L34 | M35: =+M34 | N35: =+N34 | ... AK35: =+AK34
B36: PO 注文書 | Q36: 1000 | AL36: =SUM(G36:AK36) | AN36: Tồn PO 注文の 残量 | AO36: =AL36
B37: 計画数量 kế hoạch | G37: 1000 | AL37: =SUM(G37:AK37) | AN37: Tổng nhập 総入荷数量 （A)-(B)+(C) | AO37: =AL38-AL39+AL40
B38: 実際の納品数量 số lượng thực nhập | AL38: =SUM(G38:AK38) | AM38: (A) | AN38: Số lượng chưa khai tháng trước 先月まだ税関に申告されていない数量 | AO38: =AO31
B39: NG数量（DO SUNG 社変更済） số lượng NG (Trả hàng DO SUNG) | AL39: =SUM(G39:AK39) | AM39: (B) | AN39: Số lượng đã khai tháng này 今月税関に申告された数量
B40: NG数量（ドンスン 社しゅり済） số lượng NG (DO SUNG đã sửa ) | AL40: =SUM(G40:AK40) | AM40: (C) | AN40: Số lượng còn lại chưa khai 残りの数量はまだ税関に申告されていません | AO40: =AO38+AO37-AO39

Sheet mda0019
B1: LỊCH GIAO HÀNG DO SUNG DO SUNG会社の納品スケジュール
B5: 2026 | D5: 年 | E5: 2 | F5: 月
A6: mda0019 Thân khóa tay cầm (không khóa) ンドルロック本体 (キー無し) | B6: 輸送 | D6: 日 | G6: =DATE(B5,E5,1) | H6: =IF(G6="","",IF(DAY(G6+1)=1,"",G6+1)) | I6: =IF(H6="","",IF(DAY(H6+1)=1,"",H6+1)) | J6: =IF(I6="","",IF(DAY(I6+1)=1,"",I6+1)) | K6: =IF(J6="","",IF(DAY(J6+1)=1,"",J6+1)) | L6: =IF(K6="","",IF(DAY(K6+1)=1,"",K6+1)) | M6: =IF(L6="","",IF(DAY(L6+1)=1,"",L6+1)) | N6: =IF(M6="","",IF(DAY(M6+1)=1,"",M6+1)) | O6: =IF(N6="","",IF(DAY(N6+1)=1,"",N6+1)) | ... AK6: =IF(AJ6="","",IF(DAY(AJ6+1)=1,"",AJ6+1)) | AL6: Total
D7: 時間 | G7: =+G6 | H7: =+H6 | I7: =+I6 | J7: =+J6 | K7: =+K6 | L7: =+L6 | M7: =+M6 | N7: =+N6 | ... AK7: =+AK6
B8: PO 注文書 | AL8: =SUM(G8:AK8) | AN8: Tồn PO 注文の 残量
B9: 計画数量 kế hoạch | AL9: =SUM(G9:AK9) | AN9: Tổng nhập 総入荷数量 （A)-(B)+(C) | AO9: =AL10-AL11+AL12
B10: 実際の納品数量 số lượng thực nhập | AG10: 50 | AL10: =SUM(G10:AK10) | AM10: (A) | AN10: Số lượng chưa khai tháng trước 先月まだ税関に申告されていない数量
B11: NG数量（DO SUNG 社変更済） số lượng NG (Trả hàng DO SUNG) | AL11: =SUM(G11:AK11) | AM11: (B) | AN11: Số lượng đã khai tháng này 今月税関に申告された数量
B12: NG数量（ドンスン 社しゅり済） số lượng NG (DO SUNG đã sửa ) | AL12: =SUM(G12:AK12) | AM12: (C) | AN12: Số lượng còn lại chưa khai 残りの数量はまだ税関に申告されていません | AO12: =AO10+AO9-AO11
B14: 2026 | D14: 年 | E14: 3 | F14: 月
A15: mda0019 Thân khóa tay cầm (không khóa) ンドルロック本体 (キー無し) | B15: 輸送 | D15: 日 | G15: =DATE(B14,E14,1) | H15: =IF(G15="","",IF(DAY(G15+1)=1,"",G15+1)) | I15: =IF(H15="","",IF(DAY(H15+1)=1,"",H15+1)) | J15: =IF(I15="","",IF(DAY(I15+1)=1,"",I15+1)) | K15: =IF(J15="","",IF(DAY(J15+1)=1,"",J15+1)) | L15: =IF(K15="","",IF(DAY(K15+1)=1,"",K15+1)) | M15: =IF(L15="","",IF(DAY(L15+1)=1,"",L15+1)) | N15: =IF(M15="","",IF(DAY(M15+1)=1,"",M15+1)) | O15: =IF(N15="","",IF(DAY(N15+1)=1,"",N15+1)) | ... AK15: =IF(AJ15="","",IF(DAY(AJ15+1)=1,"",AJ15+1)) | AL15: Total
D16: 時間 | G16: =+G15 | H16: =+H15 | I16: =+I15 | J16: =+J15 | K16: =+K15 | L16: =+L15 | M16: =+M15 | N16: =+N15 | ... AK16: =+AK15
B17: PO 注文書 | K17: 2200 | AL17: =SUM(G17:AK17) | AN17: Tồn PO 注文の 残量 | AO17: =AO12+AL17-AO18
B18: 計画数量 kế hoạch | AL18: =SUM(G18:AK18) | AN18: Tổng nhập 総入荷数量 （A)-(B)+(C) | AO18: =AL19-AL20+AL21
B19: 実際の納品数量 số lượng thực nhập | J19: 3 | O19: 2150 | AL19: =SUM(G19:AK19) | AM19: (A) | AN19: Số lượng chưa khai tháng trước 先月まだ税関に申告されていない数量 | AO19: =AO12
B20: NG数量（DO SUNG 社変更済） số lượng NG (Trả hàng DO SUNG) | AL20: =SUM(G20:AK20) | AM20: (B) | AN20: Số lượng đã khai tháng này 今月税関に申告された数量 | AO20: 2200
B21: NG数量（ドンスン 社しゅり済） số lượng NG (DO SUNG đã sửa ) | AL21: =SUM(G21:AK21) | AM21: (C) | AN21: Số lượng còn lại chưa khai 残りの数量はまだ税関に申告されていません | AO21: =AO19+AO18-AO20
B23: 2026 | D23: 年 | E23: 5 | F23: 月
A24: mda0019 Thân khóa tay cầm (không khóa) ンドルロック本体 (キー無し) | B24: 輸送 | D24: 日 | G24: =DATE(B23,E23,1) | H24: =IF(G24="","",IF(DAY(G24+1)=1,"",G24+1)) | I24: =IF(H24="","",IF(DAY(H24+1)=1,"",H24+1)) | J24: =IF(I24="","",IF(DAY(I24+1)=1,"",I24+1)) | K24: =IF(J24="","",IF(DAY(J24+1)=1,"",J24+1)) | L24: =IF(K24="","",IF(DAY(K24+1)=1,"",K24+1)) | M24: =IF(L24="","",IF(DAY(L24+1)=1,"",L24+1)) | N24: =IF(M24="","",IF(DAY(M24+1)=1,"",M24+1)) | O24: =IF(N24="","",IF(DAY(N24+1)=1,"",N24+1)) | ... AK24: =IF(AJ24="","",IF(DAY(AJ24+1)=1,"",AJ24+1)) | AL24: Total
D25: 時間 | G25: =+G24 | H25: =+H24 | I25: =+I24 | J25: =+J24 | K25: =+K24 | L25: =+L24 | M25: =+M24 | N25: =+N24 | ... AK25: =+AK24
B26: PO 注文書 | L26: 1200 | AL26: =SUM(G26:AK26) | AN26: Tồn PO 注文の 残量 | AO26: =AO21+AL26-AO27
B27: 計画数量 kế hoạch | AL27: =SUM(G27:AK27) | AN27: Tổng nhập 総入荷数量 （A)-(B)+(C) | AO27: =AL28-AL29+AL30
B28: 実際の納品数量 số lượng thực nhập | Q28: 1200 | AL28: =SUM(G28:AK28) | AM28: (A) | AN28: Số lượng chưa khai tháng trước 先月まだ税関に申告されていない数量 | AO28: =AO21
B29: NG数量（DO SUNG 社変更済） số lượng NG (Trả hàng DO SUNG) | T29: 125 | AL29: =SUM(G29:AK29) | AM29: (B) | AN29: Số lượng đã khai tháng này 今月税関に申告された数量 | AO29: 1200
B30: NG数量（ドンスン 社しゅり済） số lượng NG (DO SUNG đã sửa ) | Q30: 21 | T30: =114-10 | AL30: =SUM(G30:AK30) | AM30: (C) | AN30: Số lượng còn lại chưa khai 残りの数量はまだ税関に申告されていません | AO30: =AO28+AO27-AO29
B33: 2026 | D33: 年 | E33: 10 | F33: 月 | Q33: 11/07/2026 đặt PO
A34: mda0019 Thân khóa tay cầm (không khóa) ンドルロック本体 (キー無し) | B34: 輸送 | D34: 日 | G34: =DATE(B33,E33,1) | H34: =IF(G34="","",IF(DAY(G34+1)=1,"",G34+1)) | I34: =IF(H34="","",IF(DAY(H34+1)=1,"",H34+1)) | J34: =IF(I34="","",IF(DAY(I34+1)=1,"",I34+1)) | K34: =IF(J34="","",IF(DAY(J34+1)=1,"",J34+1)) | L34: =IF(K34="","",IF(DAY(K34+1)=1,"",K34+1)) | M34: =IF(L34="","",IF(DAY(L34+1)=1,"",L34+1)) | N34: =IF(M34="","",IF(DAY(M34+1)=1,"",M34+1)) | O34: =IF(N34="","",IF(DAY(N34+1)=1,"",N34+1)) | ... AK34: =IF(AJ34="","",IF(DAY(AJ34+1)=1,"",AJ34+1)) | AL34: Total
D35: 時間 | G35: =+G34 | H35: =+H34 | I35: =+I34 | J35: =+J34 | K35: =+K34 | L35: =+L34 | M35: =+M34 | N35: =+N34 | ... AK35: =+AK34
B36: PO 注文書 | Q36: 1000 | AL36: =SUM(G36:AK36) | AN36: Tồn PO 注文の 残量 | AO36: =AL36
B37: 計画数量 kế hoạch | G37: 1000 | AL37: =SUM(G37:AK37) | AN37: Tổng nhập 総入荷数量 （A)-(B)+(C) | AO37: =AL38-AL39+AL40
B38: 実際の納品数量 số lượng thực nhập | AL38: =SUM(G38:AK38) | AM38: (A) | AN38: Số lượng chưa khai tháng trước 先月まだ税関に申告されていない数量 | AO38: =AO31
B39: NG数量（DO SUNG 社変更済） số lượng NG (Trả hàng DO SUNG) | AL39: =SUM(G39:AK39) | AM39: (B) | AN39: Số lượng đã khai tháng này 今月税関に申告された数量
B40: NG数量（ドンスン 社しゅり済） số lượng NG (DO SUNG đã sửa ) | AL40: =SUM(G40:AK40) | AM40: (C) | AN40: Số lượng còn lại chưa khai 残りの数量はまだ税関に申告されていません | AO40: =AO38+AO37-AO39

Sheet mta0002
B1: LỊCH GIAO HÀNG DO SUNG DO SUNG会社の納品スケジュール
B5: 2026 | D5: 年 | E5: 3 | F5: 月
A6: mta0002 khớp nối New Jointer PA006 | B6: 輸送 | D6: 日 | G6: =DATE(B5,E5,1) | H6: =IF(G6="","",IF(DAY(G6+1)=1,"",G6+1)) | I6: =IF(H6="","",IF(DAY(H6+1)=1,"",H6+1)) | J6: =IF(I6="","",IF(DAY(I6+1)=1,"",I6+1)) | K6: =IF(J6="","",IF(DAY(J6+1)=1,"",J6+1)) | L6: =IF(K6="","",IF(DAY(K6+1)=1,"",K6+1)) | M6: =IF(L6="","",IF(DAY(L6+1)=1,"",L6+1)) | N6: =IF(M6="","",IF(DAY(M6+1)=1,"",M6+1)) | O6: =IF(N6="","",IF(DAY(N6+1)=1,"",N6+1)) | ... AK6: =IF(AJ6="","",IF(DAY(AJ6+1)=1,"",AJ6+1)) | AL6: Total
D7: 時間 | G7: =+G6 | H7: =+H6 | I7: =+I6 | J7: =+J6 | K7: =+K6 | L7: =+L6 | M7: =+M6 | N7: =+N6 | ... AK7: =+AK6
B8: PO 注文書 | V8: 2000 | AL8: =SUM(G8:AK8) | AN8: Tồn PO 注文の 残量 | AO8: =AL8-AO9
B9: 計画数量 kế hoạch | AL9: =SUM(G9:AK9) | AN9: Tổng nhập 総入荷数量 （A)-(B)+(C) | AO9: =AL10-AL11+AL12
B10: 実際の納品数量 số lượng thực nhập | AL10: =SUM(G10:AK10) | AM10: (A) | AN10: Số lượng chưa khai tháng trước 先月まだ税関に申告されていない数量
B11: NG数量（DO SUNG 社変更済） số lượng NG (Trả hàng DO SUNG) | AL11: =SUM(G11:AK11) | AM11: (B) | AN11: Số lượng đã khai tháng này 今月税関に申告された数量 | AO11: 700
B12: NG数量（ドンスン 社しゅり済） số lượng NG (DO SUNG đã sửa ) | AL12: =SUM(G12:AK12) | AM12: (C) | AN12: Số lượng còn lại chưa khai 残りの数量はまだ税関に申告されていません | AO12: =AO10+AO9-AO11
B14: 2026 | D14: 年 | E14: 4 | F14: 月
A15: mta0002 khớp nối New Jointer PA006 | B15: 輸送 | D15: 日 | G15: =DATE(B14,E14,1) | H15: =IF(G15="","",IF(DAY(G15+1)=1,"",G15+1)) | I15: =IF(H15="","",IF(DAY(H15+1)=1,"",H15+1)) | J15: =IF(I15="","",IF(DAY(I15+1)=1,"",I15+1)) | K15: =IF(J15="","",IF(DAY(J15+1)=1,"",J15+1)) | L15: =IF(K15="","",IF(DAY(K15+1)=1,"",K15+1)) | M15: =IF(L15="","",IF(DAY(L15+1)=1,"",L15+1)) | N15: =IF(M15="","",IF(DAY(M15+1)=1,"",M15+1)) | O15: =IF(N15="","",IF(DAY(N15+1)=1,"",N15+1)) | ... AK15: =IF(AJ15="","",IF(DAY(AJ15+1)=1,"",AJ15+1)) | AL15: Total
D16: 時間 | G16: =+G15 | H16: =+H15 | I16: =+I15 | J16: =+J15 | K16: =+K15 | L16: =+L15 | M16: =+M15 | N16: =+N15 | ... AK16: =+AK15
B17: PO 注文書 | AL17: =SUM(G17:AK17) | AN17: Tồn PO 注文の 残量 | AO17: =AO8+AL17-AO18
B18: 計画数量 kế hoạch | AL18: =SUM(G18:AK18) | AN18: Tổng nhập 総入荷数量 （A)-(B)+(C) | AO18: =AL19-AL20+AL21
B19: 実際の納品数量 số lượng thực nhập | I19: 700 | N19: 280 | O19: 440 | P19: 155 | AG19: 114 | AH19: 210 | AL19: =SUM(G19:AK19) | AM19: (A) | AN19: Số lượng chưa khai tháng trước 先月まだ税関に申告されていない数量 | AO19: =AO12
B20: NG数量（DO SUNG 社変更済） số lượng NG (Trả hàng DO SUNG) | AL20: =SUM(G20:AK20) | AM20: (B) | AN20: Số lượng đã khai tháng này 今月税関に申告された数量 | AO20: 1300
B21: NG数量（ドンスン 社しゅり済） số lượng NG (DO SUNG đã sửa ) | AL21: =SUM(G21:AK21) | AM21: (C) | AN21: Số lượng còn lại chưa khai 残りの数量はまだ税関に申告されていません | AO21: =AO19+AO18-AO20
B23: 2026 | D23: 年 | E23: 5 | F23: 月
A24: mta0002 khớp nối New Jointer PA006 | B24: 輸送 | D24: 日 | G24: =DATE(B23,E23,1) | H24: =IF(G24="","",IF(DAY(G24+1)=1,"",G24+1)) | I24: =IF(H24="","",IF(DAY(H24+1)=1,"",H24+1)) | J24: =IF(I24="","",IF(DAY(I24+1)=1,"",I24+1)) | K24: =IF(J24="","",IF(DAY(J24+1)=1,"",J24+1)) | L24: =IF(K24="","",IF(DAY(K24+1)=1,"",K24+1)) | M24: =IF(L24="","",IF(DAY(L24+1)=1,"",L24+1)) | N24: =IF(M24="","",IF(DAY(M24+1)=1,"",M24+1)) | O24: =IF(N24="","",IF(DAY(N24+1)=1,"",N24+1)) | ... AK24: =IF(AJ24="","",IF(DAY(AJ24+1)=1,"",AJ24+1)) | AL24: Total
D25: 時間 | G25: =+G24 | H25: =+H24 | I25: =+I24 | J25: =+J24 | K25: =+K24 | L25: =+L24 | M25: =+M24 | N25: =+N24 | ... AK25: =+AK24
B26: PO 注文書 | AL26: =SUM(G26:AK26) | AN26: Tồn PO 注文の 残量 | AO26: =AO17+AL26-AO27
B27: 計画数量 kế hoạch | AL27: =SUM(G27:AK27) | AN27: Tổng nhập 総入荷数量 （A)-(B)+(C) | AO27: =AL28-AL29+AL30
B28: 実際の納品数量 số lượng thực nhập | L28: 103 | AL28: =SUM(G28:AK28) | AM28: (A) | AN28: Số lượng chưa khai tháng trước 先月まだ税関に申告されていない数量 | AO28: =AO21
B29: NG数量（DO SUNG 社変更済） số lượng NG (Trả hàng DO SUNG) | L29: 132 | AL29: =SUM(G29:AK29) | AM29: (B) | AN29: Số lượng đã khai tháng này 今月税関に申告された数量
B30: NG数量（ドンスン 社しゅり済） số lượng NG (DO SUNG đã sửa ) | X30: 131 | AL30: =SUM(G30:AK30) | AM30: (C) | AN30: Số lượng còn lại chưa khai 残りの数量はまだ税関に申告されていません | AO30: =AO28+AO27-AO29
B32: 2026 | D32: 年 | E32: 6 | F32: 月
A33: mta0002 khớp nối New Jointer PA006 | B33: 輸送 | D33: 日 | G33: =DATE(B32,E32,1) | H33: =IF(G33="","",IF(DAY(G33+1)=1,"",G33+1)) | I33: =IF(H33="","",IF(DAY(H33+1)=1,"",H33+1)) | J33: =IF(I33="","",IF(DAY(I33+1)=1,"",I33+1)) | K33: =IF(J33="","",IF(DAY(J33+1)=1,"",J33+1)) | L33: =IF(K33="","",IF(DAY(K33+1)=1,"",K33+1)) | M33: =IF(L33="","",IF(DAY(L33+1)=1,"",L33+1)) | N33: =IF(M33="","",IF(DAY(M33+1)=1,"",M33+1)) | O33: =IF(N33="","",IF(DAY(N33+1)=1,"",N33+1)) | ... AK33: =IF(AJ33="","",IF(DAY(AJ33+1)=1,"",AJ33+1)) | AL33: Total
D34: 時間 | G34: =+G33 | H34: =+H33 | I34: =+I33 | J34: =+J33 | K34: =+K33 | L34: =+L33 | M34: =+M33 | N34: =+N33 | ... AK34: =+AK33
B35: PO 注文書 | U35: 2000 | AL35: =SUM(G35:AK35) | AN35: Tồn PO 注文の 残量 | AO35: =AO26+AL35-AO36
B36: 計画数量 kế hoạch | AL36: =SUM(G36:AK36) | AN36: Tổng nhập 総入荷数量 （A)-(B)+(C) | AO36: =AL37-AL38+AL39
B37: 実際の納品数量 số lượng thực nhập | W37: 400 | Z37: 1599 | AJ37: 1 | AL37: =SUM(G37:AK37) | AM37: (A) | AN37: Số lượng chưa khai tháng trước 先月まだ税関に申告されていない数量 | AO37: =AO30
B38: NG数量（DO SUNG 社変更済） số lượng NG (Trả hàng DO SUNG) | AL38: =SUM(G38:AK38) | AM38: (B) | AN38: Số lượng đã khai tháng này 今月税関に申告された数量
B39: NG数量（ドンスン 社しゅり済） số lượng NG (DO SUNG đã sửa ) | AL39: =SUM(G39:AK39) | AM39: (C) | AN39: Số lượng còn lại chưa khai 残りの数量はまだ税関に申告されていません | AO39: =AO37+AO36-AO38
B42: 2026 | D42: 年 | E42: 10 | F42: 月 | Q42: 11/07/2026 đặt PO
A43: mta0002 khớp nối New Jointer PA006 | B43: 輸送 | D43: 日 | G43: =DATE(B42,E42,1) | H43: =IF(G43="","",IF(DAY(G43+1)=1,"",G43+1)) | I43: =IF(H43="","",IF(DAY(H43+1)=1,"",H43+1)) | J43: =IF(I43="","",IF(DAY(I43+1)=1,"",I43+1)) | K43: =IF(J43="","",IF(DAY(J43+1)=1,"",J43+1)) | L43: =IF(K43="","",IF(DAY(K43+1)=1,"",K43+1)) | M43: =IF(L43="","",IF(DAY(L43+1)=1,"",L43+1)) | N43: =IF(M43="","",IF(DAY(M43+1)=1,"",M43+1)) | O43: =IF(N43="","",IF(DAY(N43+1)=1,"",N43+1)) | ... AK43: =IF(AJ43="","",IF(DAY(AJ43+1)=1,"",AJ43+1)) | AL43: Total
D44: 時間 | G44: =+G43 | H44: =+H43 | I44: =+I43 | J44: =+J43 | K44: =+K43 | L44: =+L43 | M44: =+M43 | N44: =+N43 | ... AK44: =+AK43
B45: PO 注文書 | Q45: 2000 | AL45: =SUM(G45:AK45) | AN45: Tồn PO 注文の 残量 | AO45: =AL45
B46: 計画数量 kế hoạch | G46: 2000 | AL46: =SUM(G46:AK46) | AN46: Tổng nhập 総入荷数量 （A)-(B)+(C) | AO46: =AL47-AL48+AL49
B47: 実際の納品数量 số lượng thực nhập | AL47: =SUM(G47:AK47) | AM47: (A) | AN47: Số lượng chưa khai tháng trước 先月まだ税関に申告されていない数量 | AO47: =AO40
B48: NG数量（DO SUNG 社変更済） số lượng NG (Trả hàng DO SUNG) | AL48: =SUM(G48:AK48) | AM48: (B) | AN48: Số lượng đã khai tháng này 今月税関に申告された数量
...

Sheet mta0003
B1: LỊCH GIAO HÀNG DO SUNG DO SUNG会社の納品スケジュール
B5: 2026 | D5: 年 | E5: 3 | F5: 月
A6: mta0003 khớp nối New Jointer PA006A | B6: 輸送 | D6: 日 | G6: =DATE(B5,E5,1) | H6: =IF(G6="","",IF(DAY(G6+1)=1,"",G6+1)) | I6: =IF(H6="","",IF(DAY(H6+1)=1,"",H6+1)) | J6: =IF(I6="","",IF(DAY(I6+1)=1,"",I6+1)) | K6: =IF(J6="","",IF(DAY(J6+1)=1,"",J6+1)) | L6: =IF(K6="","",IF(DAY(K6+1)=1,"",K6+1)) | M6: =IF(L6="","",IF(DAY(L6+1)=1,"",L6+1)) | N6: =IF(M6="","",IF(DAY(M6+1)=1,"",M6+1)) | O6: =IF(N6="","",IF(DAY(N6+1)=1,"",N6+1)) | ... AK6: =IF(AJ6="","",IF(DAY(AJ6+1)=1,"",AJ6+1)) | AL6: Total
D7: 時間 | G7: =+G6 | H7: =+H6 | I7: =+I6 | J7: =+J6 | K7: =+K6 | L7: =+L6 | M7: =+M6 | N7: =+N6 | ... AK7: =+AK6
B8: PO 注文書 | V8: 2000 | AL8: =SUM(G8:AK8) | AN8: Tồn PO 注文の 残量 | AO8: =AL8-AO9
B9: 計画数量 kế hoạch | AL9: =SUM(G9:AK9) | AN9: Tổng nhập 総入荷数量 （A)-(B)+(C) | AO9: =AL10-AL11+AL12
B10: 実際の納品数量 số lượng thực nhập | AL10: =SUM(G10:AK10) | AM10: (A) | AN10: Số lượng chưa khai tháng trước 先月まだ税関に申告されていない数量
B11: NG数量（DO SUNG 社変更済） số lượng NG (Trả hàng DO SUNG) | AL11: =SUM(G11:AK11) | AM11: (B) | AN11: Số lượng đã khai tháng này 今月税関に申告された数量 | AO11: 700
B12: NG数量（ドンスン 社しゅり済） số lượng NG (DO SUNG đã sửa ) | AL12: =SUM(G12:AK12) | AM12: (C) | AN12: Số lượng còn lại chưa khai 残りの数量はまだ税関に申告されていません | AO12: =AO10+AO9-AO11
B14: 2026 | D14: 年 | E14: 4 | F14: 月
A15: mta0003 khớp nối New Jointer PA006A | B15: 輸送 | D15: 日 | G15: =DATE(B14,E14,1) | H15: =IF(G15="","",IF(DAY(G15+1)=1,"",G15+1)) | I15: =IF(H15="","",IF(DAY(H15+1)=1,"",H15+1)) | J15: =IF(I15="","",IF(DAY(I15+1)=1,"",I15+1)) | K15: =IF(J15="","",IF(DAY(J15+1)=1,"",J15+1)) | L15: =IF(K15="","",IF(DAY(K15+1)=1,"",K15+1)) | M15: =IF(L15="","",IF(DAY(L15+1)=1,"",L15+1)) | N15: =IF(M15="","",IF(DAY(M15+1)=1,"",M15+1)) | O15: =IF(N15="","",IF(DAY(N15+1)=1,"",N15+1)) | ... AK15: =IF(AJ15="","",IF(DAY(AJ15+1)=1,"",AJ15+1)) | AL15: Total
D16: 時間 | G16: =+G15 | H16: =+H15 | I16: =+I15 | J16: =+J15 | K16: =+K15 | L16: =+L15 | M16: =+M15 | N16: =+N15 | ... AK16: =+AK15
B17: PO 注文書 | AL17: =SUM(G17:AK17) | AN17: Tồn PO 注文の 残量 | AO17: =AO8+AL17-AO18
B18: 計画数量 kế hoạch | AL18: =SUM(G18:AK18) | AN18: Tổng nhập 総入荷数量 （A)-(B)+(C) | AO18: =AL19-AL20+AL21
B19: 実際の納品数量 số lượng thực nhập | L19: 700 | N19: 540 | O19: 340 | P19: 97 | AG19: 280 | AH19: 43 | AL19: =SUM(G19:AK19) | AM19: (A) | AN19: Số lượng chưa khai tháng trước 先月まだ税関に申告されていない数量 | AO19: =AO12
B20: NG数量（DO SUNG 社変更済） số lượng NG (Trả hàng DO SUNG) | AL20: =SUM(G20:AK20) | AM20: (B) | AN20: Số lượng đã khai tháng này 今月税関に申告された数量 | AO20: 1300
B21: NG数量（ドンスン 社しゅり済） số lượng NG (DO SUNG đã sửa ) | AL21: =SUM(G21:AK21) | AM21: (C) | AN21: Số lượng còn lại chưa khai 残りの数量はまだ税関に申告されていません | AO21: =AO19+AO18-AO20
B23: 2026 | D23: 年 | E23: 5 | F23: 月
A24: mta0003 khớp nối New Jointer PA006A | B24: 輸送 | D24: 日 | G24: =DATE(B23,E23,1) | H24: =IF(G24="","",IF(DAY(G24+1)=1,"",G24+1)) | I24: =IF(H24="","",IF(DAY(H24+1)=1,"",H24+1)) | J24: =IF(I24="","",IF(DAY(I24+1)=1,"",I24+1)) | K24: =IF(J24="","",IF(DAY(J24+1)=1,"",J24+1)) | L24: =IF(K24="","",IF(DAY(K24+1)=1,"",K24+1)) | M24: =IF(L24="","",IF(DAY(L24+1)=1,"",L24+1)) | N24: =IF(M24="","",IF(DAY(M24+1)=1,"",M24+1)) | O24: =IF(N24="","",IF(DAY(N24+1)=1,"",N24+1)) | ... AK24: =IF(AJ24="","",IF(DAY(AJ24+1)=1,"",AJ24+1)) | AL24: Total
D25: 時間 | G25: =+G24 | H25: =+H24 | I25: =+I24 | J25: =+J24 | K25: =+K24 | L25: =+L24 | M25: =+M24 | N25: =+N24 | ... AK25: =+AK24
B26: PO 注文書 | AL26: =SUM(G26:AK26) | AN26: Tồn PO 注文の 残量 | AO26: =AO17+AL26-AO27
B27: 計画数量 kế hoạch | AL27: =SUM(G27:AK27) | AN27: Tổng nhập 総入荷数量 （A)-(B)+(C) | AO27: =AL28-AL29+AL30
B28: 実際の納品数量 số lượng thực nhập | AL28: =SUM(G28:AK28) | AM28: (A) | AN28: Số lượng chưa khai tháng trước 先月まだ税関に申告されていない数量 | AO28: =AO21
B29: NG数量（DO SUNG 社変更済） số lượng NG (Trả hàng DO SUNG) | L29: 158 | AL29: =SUM(G29:AK29) | AM29: (B) | AN29: Số lượng đã khai tháng này 今月税関に申告された数量
B30: NG数量（ドンスン 社しゅり済） số lượng NG (DO SUNG đã sửa ) | X30: 154 | AL30: =SUM(G30:AK30) | AM30: (C) | AN30: Số lượng còn lại chưa khai 残りの数量はまだ税関に申告されていません | AO30: =AO28+AO27-AO29
B32: 2026 | D32: 年 | E32: 6 | F32: 月
A33: mta0003 khớp nối New Jointer PA006A | B33: 輸送 | D33: 日 | G33: =DATE(B32,E32,1) | H33: =IF(G33="","",IF(DAY(G33+1)=1,"",G33+1)) | I33: =IF(H33="","",IF(DAY(H33+1)=1,"",H33+1)) | J33: =IF(I33="","",IF(DAY(I33+1)=1,"",I33+1)) | K33: =IF(J33="","",IF(DAY(J33+1)=1,"",J33+1)) | L33: =IF(K33="","",IF(DAY(K33+1)=1,"",K33+1)) | M33: =IF(L33="","",IF(DAY(L33+1)=1,"",L33+1)) | N33: =IF(M33="","",IF(DAY(M33+1)=1,"",M33+1)) | O33: =IF(N33="","",IF(DAY(N33+1)=1,"",N33+1)) | ... AK33: =IF(AJ33="","",IF(DAY(AJ33+1)=1,"",AJ33+1)) | AL33: Total
D34: 時間 | G34: =+G33 | H34: =+H33 | I34: =+I33 | J34: =+J33 | K34: =+K33 | L34: =+L33 | M34: =+M33 | N34: =+N33 | ... AK34: =+AK33
B35: PO 注文書 | U35: 2000 | AL35: =SUM(G35:AK35) | AN35: Tồn PO 注文の 残量 | AO35: =AO26+AL35-AO36
B36: 計画数量 kế hoạch | AL36: =SUM(G36:AK36) | AN36: Tổng nhập 総入荷数量 （A)-(B)+(C) | AO36: =AL37-AL38+AL39
B37: 実際の納品数量 số lượng thực nhập | W37: 580 | Z37: 504 | AC37: 460 | AE37: 460 | AJ37: -4 | AL37: =SUM(G37:AK37) | AM37: (A) | AN37: Số lượng chưa khai tháng trước 先月まだ税関に申告されていない数量 | AO37: =AO30
B38: NG数量（DO SUNG 社変更済） số lượng NG (Trả hàng DO SUNG) | AL38: =SUM(G38:AK38) | AM38: (B) | AN38: Số lượng đã khai tháng này 今月税関に申告された数量
B39: NG数量（ドンスン 社しゅり済） số lượng NG (DO SUNG đã sửa ) | AL39: =SUM(G39:AK39) | AM39: (C) | AN39: Số lượng còn lại chưa khai 残りの数量はまだ税関に申告されていません | AO39: =AO37+AO36-AO38
B42: 2026 | D42: 年 | E42: 10 | F42: 月 | Q42: 11/07/2026 đặt PO
A43: mta0003 khớp nối New Jointer PA006A | B43: 輸送 | D43: 日 | G43: =DATE(B42,E42,1) | H43: =IF(G43="","",IF(DAY(G43+1)=1,"",G43+1)) | I43: =IF(H43="","",IF(DAY(H43+1)=1,"",H43+1)) | J43: =IF(I43="","",IF(DAY(I43+1)=1,"",I43+1)) | K43: =IF(J43="","",IF(DAY(J43+1)=1,"",J43+1)) | L43: =IF(K43="","",IF(DAY(K43+1)=1,"",K43+1)) | M43: =IF(L43="","",IF(DAY(L43+1)=1,"",L43+1)) | N43: =IF(M43="","",IF(DAY(M43+1)=1,"",M43+1)) | O43: =IF(N43="","",IF(DAY(N43+1)=1,"",N43+1)) | ... AK43: =IF(AJ43="","",IF(DAY(AJ43+1)=1,"",AJ43+1)) | AL43: Total
D44: 時間 | G44: =+G43 | H44: =+H43 | I44: =+I43 | J44: =+J43 | K44: =+K43 | L44: =+L43 | M44: =+M43 | N44: =+N43 | ... AK44: =+AK43
B45: PO 注文書 | Q45: 2000 | AL45: =SUM(G45:AK45) | AN45: Tồn PO 注文の 残量 | AO45: =AL45
B46: 計画数量 kế hoạch | G46: 2000 | AL46: =SUM(G46:AK46) | AN46: Tổng nhập 総入荷数量 （A)-(B)+(C) | AO46: =AL47-AL48+AL49
B47: 実際の納品数量 số lượng thực nhập | AL47: =SUM(G47:AK47) | AM47: (A) | AN47: Số lượng chưa khai tháng trước 先月まだ税関に申告されていない数量 | AO47: =AO40
B48: NG数量（DO SUNG 社変更済） số lượng NG (Trả hàng DO SUNG) | AL48: =SUM(G48:AK48) | AM48: (B) | AN48: Số lượng đã khai tháng này 今月税関に申告された数量
...

Sheet Tổng nhập
M1: PAR-011 | P1: mda0010 Woodone | S1: mda0016 Tay cầm hình vuông 320
B2: Tháng | C2: PAR-011 | F2: mda0010 Woodone | I2: mda0016 Tay cầm hình vuông 320 | M2: Số Po 注文書番号 | N2: Số lượng 数量 | P2: Số Po 注文書番号 | Q2: Số lượng 数量 | S2: Số Po | T2: Số lượng
C3: Số lượng ok giao 総入荷数量 | D3: Số lượng đã lên chứng từ 今月税関に申告された数量 | E3: Số lượng chưa lên chứng từ 残りの数量はまだ税関に申告されていません | F3: Số lượng ok giao 総入荷数量 | G3: Số lượng đã lên chứng từ 今月税関に申告された数量 | H3: Số lượng chưa lên chứng từ 残りの数量はまだ税関に申告されていません | I3: Số lượng ok giao | J3: Số lượng đã lên chứng từ | K3: Số lượng chưa lên chứng từ | M3: 240801-02 | N3: 50000 | P3: 251107-02 | Q3: 40000 | S3: 251126-01 | T3: 1000
B4: 2025.08 | C4: 25799 | D4: 24830 | E4: 969 | M4: 251121-03 | N4: 30000 | U4: =N3+N4-5000
B5: 2025.09 | C5: 24201 | D5: 25170 | E5: 0 | M5: 260102-08 | N5: 25000
B6: 2025.10 | C6: -5004 | D6: 0 | E6: -5004 | M6: 260223-01 | N6: 15000
B7: 2025.11 | C7: 900 | D7: 0 | E7: -4104 | F7: 2263 | G7: 0 | H7: 2263 | I7: 1000 | J7: 1000 | K7: 0 | M7: 260319-01-1 | N7: 30000
B8: 2025.12 | C8: 14491 | D8: 6970 | E8: 3515 | F8: 10431 | G8: 11082 | H8: 1612 | I8: 0 | J8: 0 | K8: 0 | M8: 260328-01-01 | N8: 70000
B9: 2026.01 | C9: ='PAR-011'!AO9 | D9: ='PAR-011'!AO11 | E9: ='PAR-011'!AO12 | F9: =Woodone!AO9 | G9: =Woodone!AO11 | H9: =Woodone!AO12 | M9: 260416-01-1 | N9: 90000
B10: 2026.02 | C10: ='PAR-011'!AO18 | D10: ='PAR-011'!AO20 | E10: ='PAR-011'!AO21 | F10: =Woodone!AO18 | G10: =Woodone!AO20 | H10: =Woodone!AO21
B11: 2026.03 | C11: ='PAR-011'!AO27 | D11: ='PAR-011'!AO29 | E11: ='PAR-011'!AO30
M13: Tổng PO | N13: =SUM(N3:N11) | P13: Tổng PO | Q13: =SUM(Q3:Q11) | S13: Tổng PO | T13: =SUM(T3:T10)
B14: Total | C14: =SUM(C4:C13) | D14: =SUM(D4:D13) | E14: =C14-D14 | F14: =SUM(F4:F13) | G14: =SUM(G4:G13) | H14: =F14-G14 | I14: =SUM(I4:I13) | J14: =SUM(J4:J13) | K14: =I14-J14 | M14: Đã giao | N14: =C42 | P14: Đã giao | Q14: =F14 | S14: Đã giao | T14: =I14
B15: Số Shots | C15: =C14/4 | F15: =F14/4 | I15: =I14/4 | M15: Tồn PO | N15: =N13-N14 | P15: Tồn PO | Q15: =Q13-Q14 | S15: Tồn PO | T15: =T13-T14
C18: =SUM(C4:C8)
C19: =U4-C18
B23: Tháng | C23: PAR-011
C24: Số lượng ok giao 総入荷数量 | D24: Số lượng đã lên chứng từ 今月税関に申告された数量 | E24: Số lượng chưa lên chứng từ 残りの数量はまだ税関に申告されていません
B25: 2025.08
B26: 2025.09
B27: 2025.10
B28: 2025.11 | N28: =+SUM(N29:N34)
B29: 2025.12 | C29: 56970 | M29: 251121-03 | N29: 30000
B30: 2026.01 | C30: 22702 | M30: 260102-08 | N30: 25000
B31: 2026.02 | C31: 15155 | M31: 260223-01 | N31: 15000
B32: 2026.03 | C32: 26790 | M32: 260319-01-1 | N32: 30000
B33: 2026.04 | C33: 31168 | M33: 260328-01-01 | N33: 70000
B34: 2026.05 | C34: 23694 | M34: 260416-01-1 | N34: 90000 | Y34: SHIBUTANI
B35: 2026.06 | C35: 33000 | Y35: NGÀY XUẤT HÓA ĐƠN | Z35: MÃ HÀNG | AA35: SỐ LƯỢNG
B36: 2026.07 | C36: 7200 | Y36: 01/08/2026 | Z36: PAR-011 | AA36: 10.000 PCS
B37: 2026.08 | C37: 20000
B38: 2026.09 | D38: 10000
B39: 2026.10
B40: 2026.11
B41: 2026.12
B42: Total | C42: =SUM(C25:C39) | D42: =+C42 | E42: =C42-D42
B43: Số Shots | C43: =C42/4

Sheet Woodone
B1: LỊCH GIAO HÀNG DO SUNG DO SUNG会社の納品スケジュール
B5: 2026 | D5: 年 | E5: 1 | F5: 月
A6: mda0010 Woodone | B6: 輸送 | D6: 日 | G6: =DATE(B5,E5,1) | H6: =IF(G6="","",IF(DAY(G6+1)=1,"",G6+1)) | I6: =IF(H6="","",IF(DAY(H6+1)=1,"",H6+1)) | J6: =IF(I6="","",IF(DAY(I6+1)=1,"",I6+1)) | K6: =IF(J6="","",IF(DAY(J6+1)=1,"",J6+1)) | L6: =IF(K6="","",IF(DAY(K6+1)=1,"",K6+1)) | M6: =IF(L6="","",IF(DAY(L6+1)=1,"",L6+1)) | N6: =IF(M6="","",IF(DAY(M6+1)=1,"",M6+1)) | O6: =IF(N6="","",IF(DAY(N6+1)=1,"",N6+1)) | ... AK6: =IF(AJ6="","",IF(DAY(AJ6+1)=1,"",AJ6+1)) | AL6: Total
D7: 時間 | G7: =+G6 | H7: =+H6 | I7: =+I6 | J7: =+J6 | K7: =+K6 | L7: =+L6 | M7: =+M6 | N7: =+N6 | ... AK7: =+AK6
B8: PO 注文書 | H8: 2000 | N8: 3000 | AL8: =SUM(G8:AK8) | AN8: Tồn PO 注文の 残量 | AO8: =22306+AL8-AO9
B9: 計画数量 kế hoạch | AL9: =SUM(G9:AK9) | AN9: Tổng nhập 総入荷数量 （A)-(B)+(C) | AO9: =AL10-AL11+AL12
B10: 実際の納品数量 số lượng thực nhập | I10: 2393 | N10: 1949 | S10: 1158 | Z10: 1482 | AL10: =SUM(G10:AK10) | AM10: (A) | AN10: Số lượng chưa khai tháng trước 先月まだ税関に申告されていない数量 | AO10: 1612
B11: NG数量（DO SUNG 社変更済） số lượng NG (Trả hàng DO SUNG) | AL11: =SUM(G11:AK11) | AM11: (B) | AN11: Số lượng đã khai tháng này 今月税関に申告された数量 | AO11: =5954+2640
B12: NG数量（DO SUNG 社しゅり済） số lượng NG (DO SUNG đã sửa ) | AL12: =SUM(G12:AK12) | AM12: (C) | AN12: Số lượng còn lại chưa khai 残りの数量はまだ税関に申告されていません | AO12: =AO10+AO9-AO11
B14: 2026 | D14: 年 | E14: 4 | F14: 月
A15: mda0010 Woodone | B15: 輸送 | D15: 日 | G15: =DATE(B14,E14,1) | H15: =IF(G15="","",IF(DAY(G15+1)=1,"",G15+1)) | I15: =IF(H15="","",IF(DAY(H15+1)=1,"",H15+1)) | J15: =IF(I15="","",IF(DAY(I15+1)=1,"",I15+1)) | K15: =IF(J15="","",IF(DAY(J15+1)=1,"",J15+1)) | L15: =IF(K15="","",IF(DAY(K15+1)=1,"",K15+1)) | M15: =IF(L15="","",IF(DAY(L15+1)=1,"",L15+1)) | N15: =IF(M15="","",IF(DAY(M15+1)=1,"",M15+1)) | O15: =IF(N15="","",IF(DAY(N15+1)=1,"",N15+1)) | ... AK15: =IF(AJ15="","",IF(DAY(AJ15+1)=1,"",AJ15+1)) | AL15: Total
D16: 時間 | G16: =+G15 | H16: =+H15 | I16: =+I15 | J16: =+J15 | K16: =+K15 | L16: =+L15 | M16: =+M15 | N16: =+N15 | ... AK16: =+AK15
B17: PO 注文書 | AL17: =SUM(G17:AK17) | AN17: Tồn PO 注文の 残量 | AO17: =AO12+AL17-AO18
B18: 計画数量 kế hoạch | AL18: =SUM(G18:AK18) | AN18: Tổng nhập 総入荷数量 （A)-(B)+(C) | AO18: =AL19-AL20+AL21
B19: 実際の納品数量 số lượng thực nhập | AL19: =SUM(G19:AK19) | AM19: (A) | AN19: Số lượng chưa khai tháng trước 先月まだ税関に申告されていない数量 | AO19: =AO12
B20: NG数量（DO SUNG 社変更済） số lượng NG (Trả hàng DO SUNG) | P20: 4061 | AL20: =SUM(G20:AK20) | AM20: (B) | AN20: Số lượng đã khai tháng này 今月税関に申告された数量
B21: NG数量（DO SUNG 社しゅり済） số lượng NG (DO SUNG đã sửa ) | AL21: =SUM(G21:AK21) | AM21: (C) | AN21: Số lượng còn lại chưa khai 残りの数量はまだ税関に申告されていません | AO21: =AO19+AO18-AO20
B23: 2026 | D23: 年 | E23: 8 | F23: 月
A24: mda0010 Woodone | B24: 輸送 | D24: 日 | G24: =DATE(B23,E23,1) | H24: =IF(G24="","",IF(DAY(G24+1)=1,"",G24+1)) | I24: =IF(H24="","",IF(DAY(H24+1)=1,"",H24+1)) | J24: =IF(I24="","",IF(DAY(I24+1)=1,"",I24+1)) | K24: =IF(J24="","",IF(DAY(J24+1)=1,"",J24+1)) | L24: =IF(K24="","",IF(DAY(K24+1)=1,"",K24+1)) | M24: =IF(L24="","",IF(DAY(L24+1)=1,"",L24+1)) | N24: =IF(M24="","",IF(DAY(M24+1)=1,"",M24+1)) | O24: =IF(N24="","",IF(DAY(N24+1)=1,"",N24+1)) | ... AK24: =IF(AJ24="","",IF(DAY(AJ24+1)=1,"",AJ24+1)) | AL24: Total
D25: 時間 | G25: =+G24 | H25: =+H24 | I25: =+I24 | J25: =+J24 | K25: =+K24 | L25: =+L24 | M25: =+M24 | N25: =+N24 | ... AK25: =+AK24
B26: PO 注文書 | AL26: =SUM(G26:AK26) | AN26: Tồn PO 注文の 残量 | AO26: =4061
B27: 計画数量 kế hoạch | AL27: =SUM(G27:AK27) | AN27: Tổng nhập 総入荷数量 （A)-(B)+(C) | AO27: =AL28-AL29+AL30
B28: 実際の納品数量 số lượng thực nhập | AL28: =SUM(G28:AK28) | AM28: (A) | AN28: Số lượng chưa khai tháng trước 先月まだ税関に申告されていない数量 | AO28: =AO21
B29: NG数量（DO SUNG 社変更済） số lượng NG (Trả hàng DO SUNG) | AL29: =SUM(G29:AK29) | AM29: (B) | AN29: Số lượng đã khai tháng này 今月税関に申告された数量
B30: NG数量（DO SUNG 社しゅり済） số lượng NG (DO SUNG đã sửa ) | AG30: 2200 | AL30: =SUM(G30:AK30) | AM30: (C) | AN30: Số lượng còn lại chưa khai 残りの数量はまだ税関に申告されていません | AO30: =AO28+AO27-AO29
B33: 2026 | D33: 年 | E33: 9 | F33: 月
A34: mda0010 Woodone | B34: 輸送 | D34: 日 | G34: =DATE(B33,E33,1) | H34: =IF(G34="","",IF(DAY(G34+1)=1,"",G34+1)) | I34: =IF(H34="","",IF(DAY(H34+1)=1,"",H34+1)) | J34: =IF(I34="","",IF(DAY(I34+1)=1,"",I34+1)) | K34: =IF(J34="","",IF(DAY(J34+1)=1,"",J34+1)) | L34: =IF(K34="","",IF(DAY(K34+1)=1,"",K34+1)) | M34: =IF(L34="","",IF(DAY(L34+1)=1,"",L34+1)) | N34: =IF(M34="","",IF(DAY(M34+1)=1,"",M34+1)) | O34: =IF(N34="","",IF(DAY(N34+1)=1,"",N34+1)) | ... AK34: =IF(AJ34="","",IF(DAY(AJ34+1)=1,"",AJ34+1)) | AL34: Total
D35: 時間 | G35: =+G34 | H35: =+H34 | I35: =+I34 | J35: =+J34 | K35: =+K34 | L35: =+L34 | M35: =+M34 | N35: =+N34 | ... AK35: =+AK34
B36: PO 注文書 | AL36: =SUM(G36:AK36) | AN36: Tồn PO 注文の 残量 | AO36: 1861
B37: 計画数量 kế hoạch | P37: 1861 | AL37: =SUM(G37:AK37) | AN37: Tổng nhập 総入荷数量 （A)-(B)+(C) | AO37: =AL38-AL39+AL40
B38: 実際の納品数量 số lượng thực nhập | AL38: =SUM(G38:AK38) | AM38: (A) | AN38: Số lượng chưa khai tháng trước 先月まだ税関に申告されていない数量 | AO38: =AO31
B39: NG数量（DO SUNG 社変更済） số lượng NG (Trả hàng DO SUNG) | AL39: =SUM(G39:AK39) | AM39: (B) | AN39: Số lượng đã khai tháng này 今月税関に申告された数量
B40: NG数量（DO SUNG 社しゅり済） số lượng NG (DO SUNG đã sửa ) | AL40: =SUM(G40:AK40) | AM40: (C) | AN40: Số lượng còn lại chưa khai 残りの数量はまだ税関に申告されていません | AO40: =AO38+AO37-AO39

Sheet mda0016
B1: LỊCH GIAO HÀNG DO SUNG DO SUNG会社の納品スケジュール
B5: 2026 | D5: 年 | E5: 3 | F5: 月
A6: mda0016 Tay cầm hình vuông 320 スクエア取っ手 (WN73057B-320) | B6: 輸送 | D6: 日 | G6: =DATE(B5,E5,1) | H6: =IF(G6="","",IF(DAY(G6+1)=1,"",G6+1)) | I6: =IF(H6="","",IF(DAY(H6+1)=1,"",H6+1)) | J6: =IF(I6="","",IF(DAY(I6+1)=1,"",I6+1)) | K6: =IF(J6="","",IF(DAY(J6+1)=1,"",J6+1)) | L6: =IF(K6="","",IF(DAY(K6+1)=1,"",K6+1)) | M6: =IF(L6="","",IF(DAY(L6+1)=1,"",L6+1)) | N6: =IF(M6="","",IF(DAY(M6+1)=1,"",M6+1)) | O6: =IF(N6="","",IF(DAY(N6+1)=1,"",N6+1)) | ... AK6: =IF(AJ6="","",IF(DAY(AJ6+1)=1,"",AJ6+1)) | AL6: Total
D7: 時間 | G7: =+G6 | H7: =+H6 | I7: =+I6 | J7: =+J6 | K7: =+K6 | L7: =+L6 | M7: =+M6 | N7: =+N6 | ... AK7: =+AK6
B8: PO 注文書 | T8: 500 | AC8: =1000+500 | AL8: =SUM(G8:AK8) | AN8: Tồn PO 注文の 残量 | AO8: Đã hủy PO
B9: 計画数量 kế hoạch | AL9: =SUM(G9:AK9) | AN9: Tổng nhập 総入荷数量 （A)-(B)+(C) | AO9: =AL10-AL11+AL12
B10: 実際の納品数量 số lượng thực nhập | AL10: =SUM(G10:AK10) | AM10: (A) | AN10: Số lượng chưa khai tháng trước 先月まだ税関に申告されていない数量
B11: NG数量（DO SUNG 社変更済） số lượng NG (Trả hàng DO SUNG) | AL11: =SUM(G11:AK11) | AM11: (B) | AN11: Số lượng đã khai tháng này 今月税関に申告された数量
B12: NG数量（ドンスン 社しゅり済） số lượng NG (DO SUNG đã sửa ) | AL12: =SUM(G12:AK12) | AM12: (C) | AN12: Số lượng còn lại chưa khai 残りの数量はまだ税関に申告されていません | AO12: =AO10+AO9-AO11
